Workbook

Sheet 00_LEER_PRIMERO
A1: Medición agosto 2026 | B1: Medición agosto 2026 | C1: Medición agosto 2026 | D1: Medición agosto 2026 | E1: Medición agosto 2026 | F1: Medición agosto 2026 | G1: Medición agosto 2026 | H1: Medición agosto 2026 | I1: Medición agosto 2026 | J1: Medición agosto 2026
A2: Medición digital no probabilística + modelo electoral · versión para revisión técnica. | B2: Medición digital no probabilística + modelo electoral · versión para revisión técnica. | C2: Medición digital no probabilística + modelo electoral · versión para revisión técnica. | D2: Medición digital no probabilística + modelo electoral · versión para revisión técnica. | E2: Medición digital no probabilística + modelo electoral · versión para revisión técnica. | F2: Medición digital no probabilística + modelo electoral · versión para revisión técnica. | G2: Medición digital no probabilística + modelo electoral · versión para revisión técnica. | H2: Medición digital no probabilística + modelo electoral · versión para revisión técnica. | I2: Medición digital no probabilística + modelo electoral · versión para revisión técnica. | J2: Medición digital no probabilística + modelo electoral · versión para revisión técnica.
A3: VERSIÓN PRELIMINAR · El enlace individual de los registros con el padrón se está reconstruyendo. El resultado actual usa vinculación probabilística. | B3: VERSIÓN PRELIMINAR · El enlace individual de los registros con el padrón se está reconstruyendo. El resultado actual usa vinculación probabilística. | C3: VERSIÓN PRELIMINAR · El enlace individual de los registros con el padrón se está reconstruyendo. El resultado actual usa vinculación probabilística. | D3: VERSIÓN PRELIMINAR · El enlace individual de los registros con el padrón se está reconstruyendo. El resultado actual usa vinculación probabilística. | E3: VERSIÓN PRELIMINAR · El enlace individual de los registros con el padrón se está reconstruyendo. El resultado actual usa vinculación probabilística. | F3: VERSIÓN PRELIMINAR · El enlace individual de los registros con el padrón se está reconstruyendo. El resultado actual usa vinculación probabilística. | G3: VERSIÓN PRELIMINAR · El enlace individual de los registros con el padrón se está reconstruyendo. El resultado actual usa vinculación probabilística. | H3: VERSIÓN PRELIMINAR · El enlace individual de los registros con el padrón se está reconstruyendo. El resultado actual usa vinculación probabilística. | I3: VERSIÓN PRELIMINAR · El enlace individual de los registros con el padrón se está reconstruyendo. El resultado actual usa vinculación probabilística. | J3: VERSIÓN PRELIMINAR · El enlace individual de los registros con el padrón se está reconstruyendo. El resultado actual usa vinculación probabilística.
A5: Resultado actual del modelo | B5: Resultado actual del modelo | C5: Resultado actual del modelo | D5: Resultado actual del modelo | E5: Resultado actual del modelo | F5: Resultado actual del modelo | G5: Resultado actual del modelo | H5: Resultado actual del modelo | I5: Resultado actual del modelo | J5: Resultado actual del modelo
A6: Carlos Pereira Rieve | B6: Carlos Pereira Rieve | C6: Carlos Pereira Rieve | D6: Carlos Pereira Rieve | F6: Sebastian "Cheba" Remesowski | G6: Sebastian "Cheba" Remesowski | H6: Sebastian "Cheba" Remesowski | I6: Sebastian "Cheba" Remesowski
A7: ='01_RESULTADO_AGOSTO'!B8 -> 0.48586581 | F7: ='01_RESULTADO_AGOSTO'!C8 -> 0.51413419
A10: ="Lectura técnica: "&'01_RESULTADO_AGOSTO'!B29&". La diferencia es corta y la competencia permanece abierta." -> Lectura técnica: Sin liderazgo robustamente identificable bajo autoselección no observada. La diferencia es corta y la competencia permanece abierta.
A13: Qué ya está hecho | B13: Qué ya está hecho | C13: Qué ya está hecho | D13: Qué ya está hecho | E13: Qué ya está hecho | F13: Qué falta completar | G13: Qué falta completar | H13: Qué falta completar | I13: Qué falta completar | J13: Qué falta completar
A14: ✓ 3.665 respuestas históricas congeladas ✓ 1.735 Pereira y 1.930 Cheba ✓ 70 votos posteriores separados del estimador ✓ Padrón agregado, calibración, M3 y controles auditables | B14: ✓ 3.665 respuestas históricas congeladas ✓ 1.735 Pereira y 1.930 Cheba ✓ 70 votos posteriores separados del estimador ✓ Padrón agregado, calibración, M3 y controles auditables | C14: ✓ 3.665 respuestas históricas congeladas ✓ 1.735 Pereira y 1.930 Cheba ✓ 70 votos posteriores separados del estimador ✓ Padrón agregado, calibración, M3 y controles auditables | D14: ✓ 3.665 respuestas históricas congeladas ✓ 1.735 Pereira y 1.930 Cheba ✓ 70 votos posteriores separados del estimador ✓ Padrón agregado, calibración, M3 y controles auditables | E14: ✓ 3.665 respuestas históricas congeladas ✓ 1.735 Pereira y 1.930 Cheba ✓ 70 votos posteriores separados del estimador ✓ Padrón agregado, calibración, M3 y controles auditables | F14: El enlace individual con el padrón se está reconstruyendo. Hasta validarlo, cada registro se distribuye probabilísticamente entre celdas compatibles. Luego se recalculará y publicará la versión final. | G14: El enlace individual con el padrón se está reconstruyendo. Hasta validarlo, cada registro se distribuye probabilísticamente entre celdas compatibles. Luego se recalculará y publicará la versión final. | H14: El enlace individual con el padrón se está reconstruyendo. Hasta validarlo, cada registro se distribuye probabilísticamente entre celdas compatibles. Luego se recalculará y publicará la versión final. | I14: El enlace individual con el padrón se está reconstruyendo. Hasta validarlo, cada registro se distribuye probabilísticamente entre celdas compatibles. Luego se recalculará y publicará la versión final. | J14: El enlace individual con el padrón se está reconstruyendo. Hasta validarlo, cada registro se distribuye probabilísticamente entre celdas compatibles. Luego se recalculará y publicará la versión final.
A15: ✓ 3.665 respuestas históricas congeladas ✓ 1.735 Pereira y 1.930 Cheba ✓ 70 votos posteriores separados del estimador ✓ Padrón agregado, calibración, M3 y controles auditables | B15: ✓ 3.665 respuestas históricas congeladas ✓ 1.735 Pereira y 1.930 Cheba ✓ 70 votos posteriores separados del estimador ✓ Padrón agregado, calibración, M3 y controles auditables | C15: ✓ 3.665 respuestas históricas congeladas ✓ 1.735 Pereira y 1.930 Cheba ✓ 70 votos posteriores separados del estimador ✓ Padrón agregado, calibración, M3 y controles auditables | D15: ✓ 3.665 respuestas históricas congeladas ✓ 1.735 Pereira y 1.930 Cheba ✓ 70 votos posteriores separados del estimador ✓ Padrón agregado, calibración, M3 y controles auditables | E15: ✓ 3.665 respuestas históricas congeladas ✓ 1.735 Pereira y 1.930 Cheba ✓ 70 votos posteriores separados del estimador ✓ Padrón agregado, calibración, M3 y controles auditables | F15: El enlace individual con el padrón se está reconstruyendo. Hasta validarlo, cada registro se distribuye probabilísticamente entre celdas compatibles. Luego se recalculará y publicará la versión final. | G15: El enlace individual con el padrón se está reconstruyendo. Hasta validarlo, cada registro se distribuye probabilísticamente entre celdas compatibles. Luego se recalculará y publicará la versión final. | H15: El enlace individual con el padrón se está reconstruyendo. Hasta validarlo, cada registro se distribuye probabilísticamente entre celdas compatibles. Luego se recalculará y publicará la versión final. | I15: El enlace individual con el padrón se está reconstruyendo. Hasta validarlo, cada registro se distribuye probabilísticamente entre celdas compatibles. Luego se recalculará y publicará la versión final. | J15: El enlace individual con el padrón se está reconstruyendo. Hasta validarlo, cada registro se distribuye probabilísticamente entre celdas compatibles. Luego se recalculará y publicará la versión final.
A16: ✓ 3.665 respuestas históricas congeladas ✓ 1.735 Pereira y 1.930 Cheba ✓ 70 votos posteriores separados del estimador ✓ Padrón agregado, calibración, M3 y controles auditables | B16: ✓ 3.665 respuestas históricas congeladas ✓ 1.735 Pereira y 1.930 Cheba ✓ 70 votos posteriores separados del estimador ✓ Padrón agregado, calibración, M3 y controles auditables | C16: ✓ 3.665 respuestas históricas congeladas ✓ 1.735 Pereira y 1.930 Cheba ✓ 70 votos posteriores separados del estimador ✓ Padrón agregado, calibración, M3 y controles auditables | D16: ✓ 3.665 respuestas históricas congeladas ✓ 1.735 Pereira y 1.930 Cheba ✓ 70 votos posteriores separados del estimador ✓ Padrón agregado, calibración, M3 y controles auditables | E16: ✓ 3.665 respuestas históricas congeladas ✓ 1.735 Pereira y 1.930 Cheba ✓ 70 votos posteriores separados del estimador ✓ Padrón agregado, calibración, M3 y controles auditables | F16: El enlace individual con el padrón se está reconstruyendo. Hasta validarlo, cada registro se distribuye probabilísticamente entre celdas compatibles. Luego se recalculará y publicará la versión final. | G16: El enlace individual con el padrón se está reconstruyendo. Hasta validarlo, cada registro se distribuye probabilísticamente entre celdas compatibles. Luego se recalculará y publicará la versión final. | H16: El enlace individual con el padrón se está reconstruyendo. Hasta validarlo, cada registro se distribuye probabilísticamente entre celdas compatibles. Luego se recalculará y publicará la versión final. | I16: El enlace individual con el padrón se está reconstruyendo. Hasta validarlo, cada registro se distribuye probabilísticamente entre celdas compatibles. Luego se recalculará y publicará la versión final. | J16: El enlace individual con el padrón se está reconstruyendo. Hasta validarlo, cada registro se distribuye probabilísticamente entre celdas compatibles. Luego se recalculará y publicará la versión final.
A17: ✓ 3.665 respuestas históricas congeladas ✓ 1.735 Pereira y 1.930 Cheba ✓ 70 votos posteriores separados del estimador ✓ Padrón agregado, calibración, M3 y controles auditables | B17: ✓ 3.665 respuestas históricas congeladas ✓ 1.735 Pereira y 1.930 Cheba ✓ 70 votos posteriores separados del estimador ✓ Padrón agregado, calibración, M3 y controles auditables | C17: ✓ 3.665 respuestas históricas congeladas ✓ 1.735 Pereira y 1.930 Cheba ✓ 70 votos posteriores separados del estimador ✓ Padrón agregado, calibración, M3 y controles auditables | D17: ✓ 3.665 respuestas históricas congeladas ✓ 1.735 Pereira y 1.930 Cheba ✓ 70 votos posteriores separados del estimador ✓ Padrón agregado, calibración, M3 y controles auditables | E17: ✓ 3.665 respuestas históricas congeladas ✓ 1.735 Pereira y 1.930 Cheba ✓ 70 votos posteriores separados del estimador ✓ Padrón agregado, calibración, M3 y controles auditables | F17: El enlace individual con el padrón se está reconstruyendo. Hasta validarlo, cada registro se distribuye probabilísticamente entre celdas compatibles. Luego se recalculará y publicará la versión final. | G17: El enlace individual con el padrón se está reconstruyendo. Hasta validarlo, cada registro se distribuye probabilísticamente entre celdas compatibles. Luego se recalculará y publicará la versión final. | H17: El enlace individual con el padrón se está reconstruyendo. Hasta validarlo, cada registro se distribuye probabilísticamente entre celdas compatibles. Luego se recalculará y publicará la versión final. | I17: El enlace individual con el padrón se está reconstruyendo. Hasta validarlo, cada registro se distribuye probabilísticamente entre celdas compatibles. Luego se recalculará y publicará la versión final. | J17: El enlace individual con el padrón se está reconstruyendo. Hasta validarlo, cada registro se distribuye probabilísticamente entre celdas compatibles. Luego se recalculará y publicará la versión final.
A18: ✓ 3.665 respuestas históricas congeladas ✓ 1.735 Pereira y 1.930 Cheba ✓ 70 votos posteriores separados del estimador ✓ Padrón agregado, calibración, M3 y controles auditables | B18: ✓ 3.665 respuestas históricas congeladas ✓ 1.735 Pereira y 1.930 Cheba ✓ 70 votos posteriores separados del estimador ✓ Padrón agregado, calibración, M3 y controles auditables | C18: ✓ 3.665 respuestas históricas congeladas ✓ 1.735 Pereira y 1.930 Cheba ✓ 70 votos posteriores separados del estimador ✓ Padrón agregado, calibración, M3 y controles auditables | D18: ✓ 3.665 respuestas históricas congeladas ✓ 1.735 Pereira y 1.930 Cheba ✓ 70 votos posteriores separados del estimador ✓ Padrón agregado, calibración, M3 y controles auditables | E18: ✓ 3.665 respuestas históricas congeladas ✓ 1.735 Pereira y 1.930 Cheba ✓ 70 votos posteriores separados del estimador ✓ Padrón agregado, calibración, M3 y controles auditables | F18: El enlace individual con el padrón se está reconstruyendo. Hasta validarlo, cada registro se distribuye probabilísticamente entre celdas compatibles. Luego se recalculará y publicará la versión final. | G18: El enlace individual con el padrón se está reconstruyendo. Hasta validarlo, cada registro se distribuye probabilísticamente entre celdas compatibles. Luego se recalculará y publicará la versión final. | H18: El enlace individual con el padrón se está reconstruyendo. Hasta validarlo, cada registro se distribuye probabilísticamente entre celdas compatibles. Luego se recalculará y publicará la versión final. | I18: El enlace individual con el padrón se está reconstruyendo. Hasta validarlo, cada registro se distribuye probabilísticamente entre celdas compatibles. Luego se recalculará y publicará la versión final. | J18: El enlace individual con el padrón se está reconstruyendo. Hasta validarlo, cada registro se distribuye probabilísticamente entre celdas compatibles. Luego se recalculará y publicará la versión final.
A20: Cómo se construye el resultado | B20: Cómo se construye el resultado | C20: Cómo se construye el resultado | D20: Cómo se construye el resultado | E20: Cómo se construye el resultado | F20: Cómo se construye el resultado | G20: Cómo se construye el resultado | H20: Cómo se construye el resultado | I20: Cómo se construye el resultado | J20: Cómo se construye el resultado
A21: 1 · BASE 3.665 respuestas históricas Corte w04 congelado | B21: 1 · BASE 3.665 respuestas históricas Corte w04 congelado | C21: 2 · VÍNCULO Asignación probabilística a celdas del padrón En reconstrucción individual | D21: 2 · VÍNCULO Asignación probabilística a celdas del padrón En reconstrucción individual | E21: 2 · VÍNCULO Asignación probabilística a celdas del padrón En reconstrucción individual | F21: 3 · AJUSTE Calibración + modelo MRP Sexo, edad y territorio | G21: 3 · AJUSTE Calibración + modelo MRP Sexo, edad y territorio | H21: 4 · RESULTADO Estimación bilateral actual Condicionada al vínculo | I21: 4 · RESULTADO Estimación bilateral actual Condicionada al vínculo | J21: 4 · RESULTADO Estimación bilateral actual Condicionada al vínculo
A22: 1 · BASE 3.665 respuestas históricas Corte w04 congelado | B22: 1 · BASE 3.665 respuestas históricas Corte w04 congelado | C22: 2 · VÍNCULO Asignación probabilística a celdas del padrón En reconstrucción individual | D22: 2 · VÍNCULO Asignación probabilística a celdas del padrón En reconstrucción individual | E22: 2 · VÍNCULO Asignación probabilística a celdas del padrón En reconstrucción individual | F22: 3 · AJUSTE Calibración + modelo MRP Sexo, edad y territorio | G22: 3 · AJUSTE Calibración + modelo MRP Sexo, edad y territorio | H22: 4 · RESULTADO Estimación bilateral actual Condicionada al vínculo | I22: 4 · RESULTADO Estimación bilateral actual Condicionada al vínculo | J22: 4 · RESULTADO Estimación bilateral actual Condicionada al vínculo
A23: 1 · BASE 3.665 respuestas históricas Corte w04 congelado | B23: 1 · BASE 3.665 respuestas históricas Corte w04 congelado | C23: 2 · VÍNCULO Asignación probabilística a celdas del padrón En reconstrucción individual | D23: 2 · VÍNCULO Asignación probabilística a celdas del padrón En reconstrucción individual | E23: 2 · VÍNCULO Asignación probabilística a celdas del padrón En reconstrucción individual | F23: 3 · AJUSTE Calibración + modelo MRP Sexo, edad y territorio | G23: 3 · AJUSTE Calibración + modelo MRP Sexo, edad y territorio | H23: 4 · RESULTADO Estimación bilateral actual Condicionada al vínculo | I23: 4 · RESULTADO Estimación bilateral actual Condicionada al vínculo | J23: 4 · RESULTADO Estimación bilateral actual Condicionada al vínculo
A24: 1 · BASE 3.665 respuestas históricas Corte w04 congelado | B24: 1 · BASE 3.665 respuestas históricas Corte w04 congelado | C24: 2 · VÍNCULO Asignación probabilística a celdas del padrón En reconstrucción individual | D24: 2 · VÍNCULO Asignación probabilística a celdas del padrón En reconstrucción individual | E24: 2 · VÍNCULO Asignación probabilística a celdas del padrón En reconstrucción individual | F24: 3 · AJUSTE Calibración + modelo MRP Sexo, edad y territorio | G24: 3 · AJUSTE Calibración + modelo MRP Sexo, edad y territorio | H24: 4 · RESULTADO Estimación bilateral actual Condicionada al vínculo | I24: 4 · RESULTADO Estimación bilateral actual Condicionada al vínculo | J24: 4 · RESULTADO Estimación bilateral actual Condicionada al vínculo
A26: Dónde mirar | B26: Dónde mirar | C26: Dónde mirar | D26: Dónde mirar | E26: Dónde mirar | F26: Dónde mirar | G26: Dónde mirar | H26: Dónde mirar | I26: Dónde mirar | J26: Dónde mirar
... A35: Uso correcto: sirve para revisar el método y la dirección actual del resultado. Los porcentajes son provisionales y pueden cambiar cuando termine el enlace individual al padrón. | B35: Uso correcto: sirve para revisar el método y la dirección actual del resultado. Los porcentajes son provisionales y pueden cambiar cuando termine el enlace individual al padrón. | C35: Uso correcto: sirve para revisar el método y la dirección actual del resultado. Los porcentajes son provisionales y pueden cambiar cuando termine el enlace individual al padrón. | D35: Uso correcto: sirve para revisar el método y la dirección actual del resultado. Los porcentajes son provisionales y pueden cambiar cuando termine el enlace individual al padrón. | E35: Uso correcto: sirve para revisar el método y la dirección actual del resultado. Los porcentajes son provisionales y pueden cambiar cuando termine el enlace individual al padrón. | F35: Uso correcto: sirve para revisar el método y la dirección actual del resultado. Los porcentajes son provisionales y pueden cambiar cuando termine el enlace individual al padrón. | G35: Uso correcto: sirve para revisar el método y la dirección actual del resultado. Los porcentajes son provisionales y pueden cambiar cuando termine el enlace individual al padrón. | H35: Uso correcto: sirve para revisar el método y la dirección actual del resultado. Los porcentajes son provisionales y pueden cambiar cuando termine el enlace individual al padrón. | I35: Uso correcto: sirve para revisar el método y la dirección actual del resultado. Los porcentajes son provisionales y pueden cambiar cuando termine el enlace individual al padrón. | J35: Uso correcto: sirve para revisar el método y la dirección actual del resultado. Los porcentajes son provisionales y pueden cambiar cuando termine el enlace individual al padrón.

Sheet 01_RESULTADO_AGOSTO
A1: Resultado bilateral — agosto 2026 | B1: Resultado bilateral — agosto 2026 | C1: Resultado bilateral — agosto 2026 | D1: Resultado bilateral — agosto 2026 | E1: Resultado bilateral — agosto 2026 | F1: Resultado bilateral — agosto 2026 | G1: Resultado bilateral — agosto 2026 | H1: Resultado bilateral — agosto 2026 | I1: Resultado bilateral — agosto 2026 | J1: Resultado bilateral — agosto 2026 | K1: Resultado bilateral — agosto 2026 | L1: Resultado bilateral — agosto 2026
A2: El centro principal es M3 para el electorado registrado. Votantes probables es un escenario secundario basado en participación municipal histórica de 2021 por sexo y edad. | B2: El centro principal es M3 para el electorado registrado. Votantes probables es un escenario secundario basado en participación municipal histórica de 2021 por sexo y edad. | C2: El centro principal es M3 para el electorado registrado. Votantes probables es un escenario secundario basado en participación municipal histórica de 2021 por sexo y edad. | D2: El centro principal es M3 para el electorado registrado. Votantes probables es un escenario secundario basado en participación municipal histórica de 2021 por sexo y edad. | E2: El centro principal es M3 para el electorado registrado. Votantes probables es un escenario secundario basado en participación municipal histórica de 2021 por sexo y edad. | F2: El centro principal es M3 para el electorado registrado. Votantes probables es un escenario secundario basado en participación municipal histórica de 2021 por sexo y edad. | G2: El centro principal es M3 para el electorado registrado. Votantes probables es un escenario secundario basado en participación municipal histórica de 2021 por sexo y edad. | H2: El centro principal es M3 para el electorado registrado. Votantes probables es un escenario secundario basado en participación municipal histórica de 2021 por sexo y edad. | I2: El centro principal es M3 para el electorado registrado. Votantes probables es un escenario secundario basado en participación municipal histórica de 2021 por sexo y edad. | J2: El centro principal es M3 para el electorado registrado. Votantes probables es un escenario secundario basado en participación municipal histórica de 2021 por sexo y edad. | K2: El centro principal es M3 para el electorado registrado. Votantes probables es un escenario secundario basado en participación municipal histórica de 2021 por sexo y edad. | L2: El centro principal es M3 para el electorado registrado. Votantes probables es un escenario secundario basado en participación municipal histórica de 2021 por sexo y edad.
A3: VERSIÓN PRELIMINAR · Resultado condicionado al enlace individual probabilístico; el enlace con el padrón se está reconstruyendo. | B3: VERSIÓN PRELIMINAR · Resultado condicionado al enlace individual probabilístico; el enlace con el padrón se está reconstruyendo. | C3: VERSIÓN PRELIMINAR · Resultado condicionado al enlace individual probabilístico; el enlace con el padrón se está reconstruyendo. | D3: VERSIÓN PRELIMINAR · Resultado condicionado al enlace individual probabilístico; el enlace con el padrón se está reconstruyendo. | E3: VERSIÓN PRELIMINAR · Resultado condicionado al enlace individual probabilístico; el enlace con el padrón se está reconstruyendo. | F3: VERSIÓN PRELIMINAR · Resultado condicionado al enlace individual probabilístico; el enlace con el padrón se está reconstruyendo. | G3: VERSIÓN PRELIMINAR · Resultado condicionado al enlace individual probabilístico; el enlace con el padrón se está reconstruyendo. | H3: VERSIÓN PRELIMINAR · Resultado condicionado al enlace individual probabilístico; el enlace con el padrón se está reconstruyendo. | I3: VERSIÓN PRELIMINAR · Resultado condicionado al enlace individual probabilístico; el enlace con el padrón se está reconstruyendo. | J3: VERSIÓN PRELIMINAR · Resultado condicionado al enlace individual probabilístico; el enlace con el padrón se está reconstruyendo. | K3: VERSIÓN PRELIMINAR · Resultado condicionado al enlace individual probabilístico; el enlace con el padrón se está reconstruyendo. | L3: VERSIÓN PRELIMINAR · Resultado condicionado al enlace individual probabilístico; el enlace con el padrón se está reconstruyendo.
A4: Escalones principales | B4: Escalones principales | C4: Escalones principales | D4: Escalones principales | E4: Escalones principales | F4: Escalones principales | G4: Escalones principales | H4: Escalones principales | J4: Estimando | K4: Carlos Pereira Rieve | L4: Sebastian "Cheba" Remesowski
A5: Estimador | B5: Pereira | C5: Remesowski | D5: Brecha P−R (pp) | E5: P2,5 Pereira | F5: P97,5 Pereira | G5: Base | H5: Lectura | J5: Principal: registrados | K5: =B8 -> 0.48586581 | L5: =C8 -> 0.51413419
A6: Bruto | B6: =AVERAGE('09_BASE_AUDITABLE'!$B$2:$B$3666) -> 0.473397 | C6: =1-B6 -> 0.526603 | D6: =(B6-C6)*100 -> -5.3206003 | G6: 3665 | H6: Señal observada | J6: Secundario: participación municipal histórica de 2021 por sexo y edad | K6: =B9 -> 0.47895192 | L6: =C9 -> 0.52104808
A7: Calibrado P99 | B7: =SUMPRODUCT('09_BASE_AUDITABLE'!$B$2:$B$3666,'09_BASE_AUDITABLE'!$H$2:$H$3666)/SUM('09_BASE_AUDITABLE'!$H$2:$H$3666) -> 0.48788911 | C7: =1-B7 -> 0.51211089 | D7: =(B7-C7)*100 -> -2.4221781 | G7: 3665 | H7: Composición observable
A8: M3 registrados | B8: =AVERAGE('09_BASE_AUDITABLE'!$AA$2:$AA$4001) -> 0.48586581 | C8: =1-B8 -> 0.51413419 | D8: =(B8-C8)*100 -> -2.8268387 | E8: =PERCENTILE('09_BASE_AUDITABLE'!$AA$2:$AA$4001,0.025) -> 0.46890807 | F8: =PERCENTILE('09_BASE_AUDITABLE'!$AA$2:$AA$4001,0.975) -> 0.50249399 | G8: 4000 | H8: Estimando principal
A9: M3 votantes probables | B9: =AVERAGE('09_BASE_AUDITABLE'!$AE$2:$AE$4001) -> 0.47895192 | C9: =1-B9 -> 0.52104808 | D9: =(B9-C9)*100 -> -4.2096158 | E9: =PERCENTILE('09_BASE_AUDITABLE'!$AE$2:$AE$4001,0.025) -> 0.46222293 | F9: =PERCENTILE('09_BASE_AUDITABLE'!$AE$2:$AE$4001,0.975) -> 0.49540912 | G9: 4000 | H9: Escenario secundario: participación municipal histórica de 2021 por sexo y edad
A23: Tres niveles de incertidumbre | B23: Tres niveles de incertidumbre | C23: Tres niveles de incertidumbre | D23: Tres niveles de incertidumbre | E23: Tres niveles de incertidumbre | F23: Tres niveles de incertidumbre | G23: Tres niveles de incertidumbre | H23: Tres niveles de incertidumbre
A24: Nivel | B24: Qué mide | C24: Cómo se presenta | D24: Qué no afirma
A25: 1. Centro operativo | B25: Preferencia bilateral condicionada | C25: M3 electorado registrado | D25: No predice el resultado electoral
A26: 2. Intervalo condicional | B26: Variación posterior del modelo | C26: P2,5–P97,5 | D26: No es margen de error muestral
A27: 3. Incertidumbre estructural | B27: Autoselección y vínculo | C27: Curva Γ y sensibilidades | D27: No desaparece por ponderar
A28: Lectura condicional | B28: =IF(E8>0.5,"Ventaja condicional de Pereira entre registrados",IF(F8<0.5,"Ventaja condicional de Cheba entre registrados","Paridad condicional entre registrados")) -> Paridad condicional entre registrados | C28: Según el intervalo P2,5–P97,5 de M3 entre registrados | D28: No equivale a liderazgo robusto
A29: Conclusión de difusión | B29: =IF(MIN('07_SENSIBILIDAD'!D6:D12)>0.5,"Ventaja robusta de Pereira",IF(MAX('07_SENSIBILIDAD'!E6:E12)<0.5,"Ventaja robusta de Cheba","Sin liderazgo robustamente identificable bajo autoselección no observada")) -> Sin liderazgo robustamente identificable bajo autoselección no observada | C29: Exige estabilidad frente a sensibilidad Γ | D29: No es probabilidad de ganar
A32: Los intervalos P2,5–P97,5 son condicionales al modelo y a sus insumos. El escenario de participación municipal histórica de 2021 por sexo y edad queda separado y no sustituye al resultado principal entre registrados. | B32: Los intervalos P2,5–P97,5 son condicionales al modelo y a sus insumos. El escenario de participación municipal histórica de 2021 por sexo y edad queda separado y no sustituye al resultado principal entre registrados. | C32: Los intervalos P2,5–P97,5 son condicionales al modelo y a sus insumos. El escenario de participación municipal histórica de 2021 por sexo y edad queda separado y no sustituye al resultado principal entre registrados. | D32: Los intervalos P2,5–P97,5 son condicionales al modelo y a sus insumos. El escenario de participación municipal histórica de 2021 por sexo y edad queda separado y no sustituye al resultado principal entre registrados. | E32: Los intervalos P2,5–P97,5 son condicionales al modelo y a sus insumos. El escenario de participación municipal histórica de 2021 por sexo y edad queda separado y no sustituye al resultado principal entre registrados. | F32: Los intervalos P2,5–P97,5 son condicionales al modelo y a sus insumos. El escenario de participación municipal histórica de 2021 por sexo y edad queda separado y no sustituye al resultado principal entre registrados. | G32: Los intervalos P2,5–P97,5 son condicionales al modelo y a sus insumos. El escenario de participación municipal histórica de 2021 por sexo y edad queda separado y no sustituye al resultado principal entre registrados. | H32: Los intervalos P2,5–P97,5 son condicionales al modelo y a sus insumos. El escenario de participación municipal histórica de 2021 por sexo y edad queda separado y no sustituye al resultado principal entre registrados.
A33: Los intervalos P2,5–P97,5 son condicionales al modelo y a sus insumos. El escenario de participación municipal histórica de 2021 por sexo y edad queda separado y no sustituye al resultado principal entre registrados. | B33: Los intervalos P2,5–P97,5 son condicionales al modelo y a sus insumos. El escenario de participación municipal histórica de 2021 por sexo y edad queda separado y no sustituye al resultado principal entre registrados. | C33: Los intervalos P2,5–P97,5 son condicionales al modelo y a sus insumos. El escenario de participación municipal histórica de 2021 por sexo y edad queda separado y no sustituye al resultado principal entre registrados. | D33: Los intervalos P2,5–P97,5 son condicionales al modelo y a sus insumos. El escenario de participación municipal histórica de 2021 por sexo y edad queda separado y no sustituye al resultado principal entre registrados. | E33: Los intervalos P2,5–P97,5 son condicionales al modelo y a sus insumos. El escenario de participación municipal histórica de 2021 por sexo y edad queda separado y no sustituye al resultado principal entre registrados. | F33: Los intervalos P2,5–P97,5 son condicionales al modelo y a sus insumos. El escenario de participación municipal histórica de 2021 por sexo y edad queda separado y no sustituye al resultado principal entre registrados. | G33: Los intervalos P2,5–P97,5 son condicionales al modelo y a sus insumos. El escenario de participación municipal histórica de 2021 por sexo y edad queda separado y no sustituye al resultado principal entre registrados. | H33: Los intervalos P2,5–P97,5 son condicionales al modelo y a sus insumos. El escenario de participación municipal histórica de 2021 por sexo y edad queda separado y no sustituye al resultado principal entre registrados.
A34: Los intervalos P2,5–P97,5 son condicionales al modelo y a sus insumos. El escenario de participación municipal histórica de 2021 por sexo y edad queda separado y no sustituye al resultado principal entre registrados. | B34: Los intervalos P2,5–P97,5 son condicionales al modelo y a sus insumos. El escenario de participación municipal histórica de 2021 por sexo y edad queda separado y no sustituye al resultado principal entre registrados. | C34: Los intervalos P2,5–P97,5 son condicionales al modelo y a sus insumos. El escenario de participación municipal histórica de 2021 por sexo y edad queda separado y no sustituye al resultado principal entre registrados. | D34: Los intervalos P2,5–P97,5 son condicionales al modelo y a sus insumos. El escenario de participación municipal histórica de 2021 por sexo y edad queda separado y no sustituye al resultado principal entre registrados. | E34: Los intervalos P2,5–P97,5 son condicionales al modelo y a sus insumos. El escenario de participación municipal histórica de 2021 por sexo y edad queda separado y no sustituye al resultado principal entre registrados. | F34: Los intervalos P2,5–P97,5 son condicionales al modelo y a sus insumos. El escenario de participación municipal histórica de 2021 por sexo y edad queda separado y no sustituye al resultado principal entre registrados. | G34: Los intervalos P2,5–P97,5 son condicionales al modelo y a sus insumos. El escenario de participación municipal histórica de 2021 por sexo y edad queda separado y no sustituye al resultado principal entre registrados. | H34: Los intervalos P2,5–P97,5 son condicionales al modelo y a sus insumos. El escenario de participación municipal histórica de 2021 por sexo y edad queda separado y no sustituye al resultado principal entre registrados.
A35: Los intervalos P2,5–P97,5 son condicionales al modelo y a sus insumos. El escenario de participación municipal histórica de 2021 por sexo y edad queda separado y no sustituye al resultado principal entre registrados. | B35: Los intervalos P2,5–P97,5 son condicionales al modelo y a sus insumos. El escenario de participación municipal histórica de 2021 por sexo y edad queda separado y no sustituye al resultado principal entre registrados. | C35: Los intervalos P2,5–P97,5 son condicionales al modelo y a sus insumos. El escenario de participación municipal histórica de 2021 por sexo y edad queda separado y no sustituye al resultado principal entre registrados. | D35: Los intervalos P2,5–P97,5 son condicionales al modelo y a sus insumos. El escenario de participación municipal histórica de 2021 por sexo y edad queda separado y no sustituye al resultado principal entre registrados. | E35: Los intervalos P2,5–P97,5 son condicionales al modelo y a sus insumos. El escenario de participación municipal histórica de 2021 por sexo y edad queda separado y no sustituye al resultado principal entre registrados. | F35: Los intervalos P2,5–P97,5 son condicionales al modelo y a sus insumos. El escenario de participación municipal histórica de 2021 por sexo y edad queda separado y no sustituye al resultado principal entre registrados. | G35: Los intervalos P2,5–P97,5 son condicionales al modelo y a sus insumos. El escenario de participación municipal histórica de 2021 por sexo y edad queda separado y no sustituye al resultado principal entre registrados. | H35: Los intervalos P2,5–P97,5 son condicionales al modelo y a sus insumos. El escenario de participación municipal histórica de 2021 por sexo y edad queda separado y no sustituye al resultado principal entre registrados.

Sheet 02_ESCALERA_AJUSTES
A1: Escalera de ajustes | B1: Escalera de ajustes | C1: Escalera de ajustes | D1: Escalera de ajustes | E1: Escalera de ajustes | F1: Escalera de ajustes | G1: Escalera de ajustes | H1: Escalera de ajustes | I1: Escalera de ajustes | J1: Escalera de ajustes | K1: Escalera de ajustes
A2: Cada fila añade una corrección identificable. La convergencia entre estimadores es evidencia interna; no convierte la muestra en probabilística. | B2: Cada fila añade una corrección identificable. La convergencia entre estimadores es evidencia interna; no convierte la muestra en probabilística. | C2: Cada fila añade una corrección identificable. La convergencia entre estimadores es evidencia interna; no convierte la muestra en probabilística. | D2: Cada fila añade una corrección identificable. La convergencia entre estimadores es evidencia interna; no convierte la muestra en probabilística. | E2: Cada fila añade una corrección identificable. La convergencia entre estimadores es evidencia interna; no convierte la muestra en probabilística. | F2: Cada fila añade una corrección identificable. La convergencia entre estimadores es evidencia interna; no convierte la muestra en probabilística. | G2: Cada fila añade una corrección identificable. La convergencia entre estimadores es evidencia interna; no convierte la muestra en probabilística. | H2: Cada fila añade una corrección identificable. La convergencia entre estimadores es evidencia interna; no convierte la muestra en probabilística. | I2: Cada fila añade una corrección identificable. La convergencia entre estimadores es evidencia interna; no convierte la muestra en probabilística. | J2: Cada fila añade una corrección identificable. La convergencia entre estimadores es evidencia interna; no convierte la muestra en probabilística. | K2: Cada fila añade una corrección identificable. La convergencia entre estimadores es evidencia interna; no convierte la muestra en probabilística.
A5: Estimador | B5: Registrados | C5: Votantes probables | D5: Δ vs bruto (pp) | E5: Ajuste incorporado | F5: Fuente
A6: Bruto | B6: =AVERAGE('09_BASE_AUDITABLE'!$B$2:$B$3666) -> 0.473397 | C6: NO CALCULADO | D6: =(B6-$B$6)*100 -> 0 | E6: Ninguno | F6: Observaciones
A7: Rake sin truncar | B7: =SUMPRODUCT('09_BASE_AUDITABLE'!$B$2:$B$3666,'09_BASE_AUDITABLE'!$G$2:$G$3666)/SUM('09_BASE_AUDITABLE'!$G$2:$G$3666) -> 0.48881865 | C7: NO CALCULADO | D7: =(B7-$B$6)*100 -> 1.5421647 | E7: Sexo×edad y local | F7: Pesos
A8: Rake P99 | B8: =SUMPRODUCT('09_BASE_AUDITABLE'!$B$2:$B$3666,'09_BASE_AUDITABLE'!$H$2:$H$3666)/SUM('09_BASE_AUDITABLE'!$H$2:$H$3666) -> 0.48788911 | C8: NO CALCULADO | D8: =(B8-$B$6)*100 -> 1.4492111 | E8: Rake + control de extremos | F8: Pesos
A9: Rake P95 | B9: =SUMPRODUCT('09_BASE_AUDITABLE'!$B$2:$B$3666,'09_BASE_AUDITABLE'!$I$2:$I$3666)/SUM('09_BASE_AUDITABLE'!$I$2:$I$3666) -> 0.48836361 | C9: NO CALCULADO | D9: =(B9-$B$6)*100 -> 1.4966606 | E9: Estrés de truncamiento | F9: Pesos
A10: M1 | B10: =AVERAGE('09_BASE_AUDITABLE'!$Y$2:$Y$4001) -> 0.48602533 | C10: =AVERAGE('09_BASE_AUDITABLE'!$AC$2:$AC$4001) -> 0.47916707 | D10: =(B10-$B$6)*100 -> 1.2628331 | E10: Sexo + edad + local | F10: Simulaciones
A11: M2 | B11: =AVERAGE('09_BASE_AUDITABLE'!$Z$2:$Z$4001) -> 0.48606362 | C11: =AVERAGE('09_BASE_AUDITABLE'!$AD$2:$AD$4001) -> 0.47912558 | D11: =(B11-$B$6)*100 -> 1.2666618 | E11: M1 + sexo×edad | F11: Simulaciones
A12: M3 primario | B12: =AVERAGE('09_BASE_AUDITABLE'!$AA$2:$AA$4001) -> 0.48586581 | C12: =AVERAGE('09_BASE_AUDITABLE'!$AE$2:$AE$4001) -> 0.47895192 | D12: =(B12-$B$6)*100 -> 1.2468808 | E12: M2 + mesa anidada | F12: Simulaciones
A13: M4 robustez P99 | B13: =AVERAGE('09_BASE_AUDITABLE'!$AB$2:$AB$4001) -> 0.48852355 | C13: =AVERAGE('09_BASE_AUDITABLE'!$AF$2:$AF$4001) -> 0.48423937 | D13: =(B13-$B$6)*100 -> 1.5126551 | E13: M3 + pseudo-verosimilitud calibrada | F13: Simulaciones
A16: Lectura del ajuste | B16: Lectura del ajuste | C16: Lectura del ajuste | D16: Lectura del ajuste | E16: Lectura del ajuste | F16: Lectura del ajuste
A17: M1–M4 usan regresión logística bayesiana regularizada con efectos de sexo, edad, local y mesa, seguida de postestratificación; escalas territoriales/mesa fijadas, no hiperparámetros aprendidos. M3 es el estimador inferencial primario ajustado con NUTS. M4 se informa como robustez por selección observable. | B17: M1–M4 usan regresión logística bayesiana regularizada con efectos de sexo, edad, local y mesa, seguida de postestratificación; escalas territoriales/mesa fijadas, no hiperparámetros aprendidos. M3 es el estimador inferencial primario ajustado con NUTS. M4 se informa como robustez por selección observable. | C17: M1–M4 usan regresión logística bayesiana regularizada con efectos de sexo, edad, local y mesa, seguida de postestratificación; escalas territoriales/mesa fijadas, no hiperparámetros aprendidos. M3 es el estimador inferencial primario ajustado con NUTS. M4 se informa como robustez por selección observable. | D17: M1–M4 usan regresión logística bayesiana regularizada con efectos de sexo, edad, local y mesa, seguida de postestratificación; escalas territoriales/mesa fijadas, no hiperparámetros aprendidos. M3 es el estimador inferencial primario ajustado con NUTS. M4 se informa como robustez por selección observable. | E17: M1–M4 usan regresión logística bayesiana regularizada con efectos de sexo, edad, local y mesa, seguida de postestratificación; escalas territoriales/mesa fijadas, no hiperparámetros aprendidos. M3 es el estimador inferencial primario ajustado con NUTS. M4 se informa como robustez por selección observable. | F17: M1–M4 usan regresión logística bayesiana regularizada con efectos de sexo, edad, local y mesa, seguida de postestratificación; escalas territoriales/mesa fijadas, no hiperparámetros aprendidos. M3 es el estimador inferencial primario ajustado con NUTS. M4 se informa como robustez por selección observable.
A18: M1–M4 usan regresión logística bayesiana regularizada con efectos de sexo, edad, local y mesa, seguida de postestratificación; escalas territoriales/mesa fijadas, no hiperparámetros aprendidos. M3 es el estimador inferencial primario ajustado con NUTS. M4 se informa como robustez por selección observable. | B18: M1–M4 usan regresión logística bayesiana regularizada con efectos de sexo, edad, local y mesa, seguida de postestratificación; escalas territoriales/mesa fijadas, no hiperparámetros aprendidos. M3 es el estimador inferencial primario ajustado con NUTS. M4 se informa como robustez por selección observable. | C18: M1–M4 usan regresión logística bayesiana regularizada con efectos de sexo, edad, local y mesa, seguida de postestratificación; escalas territoriales/mesa fijadas, no hiperparámetros aprendidos. M3 es el estimador inferencial primario ajustado con NUTS. M4 se informa como robustez por selección observable. | D18: M1–M4 usan regresión logística bayesiana regularizada con efectos de sexo, edad, local y mesa, seguida de postestratificación; escalas territoriales/mesa fijadas, no hiperparámetros aprendidos. M3 es el estimador inferencial primario ajustado con NUTS. M4 se informa como robustez por selección observable. | E18: M1–M4 usan regresión logística bayesiana regularizada con efectos de sexo, edad, local y mesa, seguida de postestratificación; escalas territoriales/mesa fijadas, no hiperparámetros aprendidos. M3 es el estimador inferencial primario ajustado con NUTS. M4 se informa como robustez por selección observable. | F18: M1–M4 usan regresión logística bayesiana regularizada con efectos de sexo, edad, local y mesa, seguida de postestratificación; escalas territoriales/mesa fijadas, no hiperparámetros aprendidos. M3 es el estimador inferencial primario ajustado con NUTS. M4 se informa como robustez por selección observable.
A19: M1–M4 usan regresión logística bayesiana regularizada con efectos de sexo, edad, local y mesa, seguida de postestratificación; escalas territoriales/mesa fijadas, no hiperparámetros aprendidos. M3 es el estimador inferencial primario ajustado con NUTS. M4 se informa como robustez por selección observable. | B19: M1–M4 usan regresión logística bayesiana regularizada con efectos de sexo, edad, local y mesa, seguida de postestratificación; escalas territoriales/mesa fijadas, no hiperparámetros aprendidos. M3 es el estimador inferencial primario ajustado con NUTS. M4 se informa como robustez por selección observable. | C19: M1–M4 usan regresión logística bayesiana regularizada con efectos de sexo, edad, local y mesa, seguida de postestratificación; escalas territoriales/mesa fijadas, no hiperparámetros aprendidos. M3 es el estimador inferencial primario ajustado con NUTS. M4 se informa como robustez por selección observable. | D19: M1–M4 usan regresión logística bayesiana regularizada con efectos de sexo, edad, local y mesa, seguida de postestratificación; escalas territoriales/mesa fijadas, no hiperparámetros aprendidos. M3 es el estimador inferencial primario ajustado con NUTS. M4 se informa como robustez por selección observable. | E19: M1–M4 usan regresión logística bayesiana regularizada con efectos de sexo, edad, local y mesa, seguida de postestratificación; escalas territoriales/mesa fijadas, no hiperparámetros aprendidos. M3 es el estimador inferencial primario ajustado con NUTS. M4 se informa como robustez por selección observable. | F19: M1–M4 usan regresión logística bayesiana regularizada con efectos de sexo, edad, local y mesa, seguida de postestratificación; escalas territoriales/mesa fijadas, no hiperparámetros aprendidos. M3 es el estimador inferencial primario ajustado con NUTS. M4 se informa como robustez por selección observable.
A20: M1–M4 usan regresión logística bayesiana regularizada con efectos de sexo, edad, local y mesa, seguida de postestratificación; escalas territoriales/mesa fijadas, no hiperparámetros aprendidos. M3 es el estimador inferencial primario ajustado con NUTS. M4 se informa como robustez por selección observable. | B20: M1–M4 usan regresión logística bayesiana regularizada con efectos de sexo, edad, local y mesa, seguida de postestratificación; escalas territoriales/mesa fijadas, no hiperparámetros aprendidos. M3 es el estimador inferencial primario ajustado con NUTS. M4 se informa como robustez por selección observable. | C20: M1–M4 usan regresión logística bayesiana regularizada con efectos de sexo, edad, local y mesa, seguida de postestratificación; escalas territoriales/mesa fijadas, no hiperparámetros aprendidos. M3 es el estimador inferencial primario ajustado con NUTS. M4 se informa como robustez por selección observable. | D20: M1–M4 usan regresión logística bayesiana regularizada con efectos de sexo, edad, local y mesa, seguida de postestratificación; escalas territoriales/mesa fijadas, no hiperparámetros aprendidos. M3 es el estimador inferencial primario ajustado con NUTS. M4 se informa como robustez por selección observable. | E20: M1–M4 usan regresión logística bayesiana regularizada con efectos de sexo, edad, local y mesa, seguida de postestratificación; escalas territoriales/mesa fijadas, no hiperparámetros aprendidos. M3 es el estimador inferencial primario ajustado con NUTS. M4 se informa como robustez por selección observable. | F20: M1–M4 usan regresión logística bayesiana regularizada con efectos de sexo, edad, local y mesa, seguida de postestratificación; escalas territoriales/mesa fijadas, no hiperparámetros aprendidos. M3 es el estimador inferencial primario ajustado con NUTS. M4 se informa como robustez por selección observable.
A21: M1–M4 usan regresión logística bayesiana regularizada con efectos de sexo, edad, local y mesa, seguida de postestratificación; escalas territoriales/mesa fijadas, no hiperparámetros aprendidos. M3 es el estimador inferencial primario ajustado con NUTS. M4 se informa como robustez por selección observable. | B21: M1–M4 usan regresión logística bayesiana regularizada con efectos de sexo, edad, local y mesa, seguida de postestratificación; escalas territoriales/mesa fijadas, no hiperparámetros aprendidos. M3 es el estimador inferencial primario ajustado con NUTS. M4 se informa como robustez por selección observable. | C21: M1–M4 usan regresión logística bayesiana regularizada con efectos de sexo, edad, local y mesa, seguida de postestratificación; escalas territoriales/mesa fijadas, no hiperparámetros aprendidos. M3 es el estimador inferencial primario ajustado con NUTS. M4 se informa como robustez por selección observable. | D21: M1–M4 usan regresión logística bayesiana regularizada con efectos de sexo, edad, local y mesa, seguida de postestratificación; escalas territoriales/mesa fijadas, no hiperparámetros aprendidos. M3 es el estimador inferencial primario ajustado con NUTS. M4 se informa como robustez por selección observable. | E21: M1–M4 usan regresión logística bayesiana regularizada con efectos de sexo, edad, local y mesa, seguida de postestratificación; escalas territoriales/mesa fijadas, no hiperparámetros aprendidos. M3 es el estimador inferencial primario ajustado con NUTS. M4 se informa como robustez por selección observable. | F21: M1–M4 usan regresión logística bayesiana regularizada con efectos de sexo, edad, local y mesa, seguida de postestratificación; escalas territoriales/mesa fijadas, no hiperparámetros aprendidos. M3 es el estimador inferencial primario ajustado con NUTS. M4 se informa como robustez por selección observable.
A23: Si M1–M4 se dispersan materialmente, la especificación domina el resultado y debe informarse como inestabilidad. La hoja 03 muestra esa dispersión con las mismas simulaciones del archivo NPZ. | B23: Si M1–M4 se dispersan materialmente, la especificación domina el resultado y debe informarse como inestabilidad. La hoja 03 muestra esa dispersión con las mismas simulaciones del archivo NPZ. | C23: Si M1–M4 se dispersan materialmente, la especificación domina el resultado y debe informarse como inestabilidad. La hoja 03 muestra esa dispersión con las mismas simulaciones del archivo NPZ. | D23: Si M1–M4 se dispersan materialmente, la especificación domina el resultado y debe informarse como inestabilidad. La hoja 03 muestra esa dispersión con las mismas simulaciones del archivo NPZ. | E23: Si M1–M4 se dispersan materialmente, la especificación domina el resultado y debe informarse como inestabilidad. La hoja 03 muestra esa dispersión con las mismas simulaciones del archivo NPZ. | F23: Si M1–M4 se dispersan materialmente, la especificación domina el resultado y debe informarse como inestabilidad. La hoja 03 muestra esa dispersión con las mismas simulaciones del archivo NPZ.
A24: Si M1–M4 se dispersan materialmente, la especificación domina el resultado y debe informarse como inestabilidad. La hoja 03 muestra esa dispersión con las mismas simulaciones del archivo NPZ. | B24: Si M1–M4 se dispersan materialmente, la especificación domina el resultado y debe informarse como inestabilidad. La hoja 03 muestra esa dispersión con las mismas simulaciones del archivo NPZ. | C24: Si M1–M4 se dispersan materialmente, la especificación domina el resultado y debe informarse como inestabilidad. La hoja 03 muestra esa dispersión con las mismas simulaciones del archivo NPZ. | D24: Si M1–M4 se dispersan materialmente, la especificación domina el resultado y debe informarse como inestabilidad. La hoja 03 muestra esa dispersión con las mismas simulaciones del archivo NPZ. | E24: Si M1–M4 se dispersan materialmente, la especificación domina el resultado y debe informarse como inestabilidad. La hoja 03 muestra esa dispersión con las mismas simulaciones del archivo NPZ. | F24: Si M1–M4 se dispersan materialmente, la especificación domina el resultado y debe informarse como inestabilidad. La hoja 03 muestra esa dispersión con las mismas simulaciones del archivo NPZ.
A25: Si M1–M4 se dispersan materialmente, la especificación domina el resultado y debe informarse como inestabilidad. La hoja 03 muestra esa dispersión con las mismas simulaciones del archivo NPZ. | B25: Si M1–M4 se dispersan materialmente, la especificación domina el resultado y debe informarse como inestabilidad. La hoja 03 muestra esa dispersión con las mismas simulaciones del archivo NPZ. | C25: Si M1–M4 se dispersan materialmente, la especificación domina el resultado y debe informarse como inestabilidad. La hoja 03 muestra esa dispersión con las mismas simulaciones del archivo NPZ. | D25: Si M1–M4 se dispersan materialmente, la especificación domina el resultado y debe informarse como inestabilidad. La hoja 03 muestra esa dispersión con las mismas simulaciones del archivo NPZ. | E25: Si M1–M4 se dispersan materialmente, la especificación domina el resultado y debe informarse como inestabilidad. La hoja 03 muestra esa dispersión con las mismas simulaciones del archivo NPZ. | F25: Si M1–M4 se dispersan materialmente, la especificación domina el resultado y debe informarse como inestabilidad. La hoja 03 muestra esa dispersión con las mismas simulaciones del archivo NPZ.
A26: Si M1–M4 se dispersan materialmente, la especificación domina el resultado y debe informarse como inestabilidad. La hoja 03 muestra esa dispersión con las mismas simulaciones del archivo NPZ. | B26: Si M1–M4 se dispersan materialmente, la especificación domina el resultado y debe informarse como inestabilidad. La hoja 03 muestra esa dispersión con las mismas simulaciones del archivo NPZ. | C26: Si M1–M4 se dispersan materialmente, la especificación domina el resultado y debe informarse como inestabilidad. La hoja 03 muestra esa dispersión con las mismas simulaciones del archivo NPZ. | D26: Si M1–M4 se dispersan materialmente, la especificación domina el resultado y debe informarse como inestabilidad. La hoja 03 muestra esa dispersión con las mismas simulaciones del archivo NPZ. | E26: Si M1–M4 se dispersan materialmente, la especificación domina el resultado y debe informarse como inestabilidad. La hoja 03 muestra esa dispersión con las mismas simulaciones del archivo NPZ. | F26: Si M1–M4 se dispersan materialmente, la especificación domina el resultado y debe informarse como inestabilidad. La hoja 03 muestra esa dispersión con las mismas simulaciones del archivo NPZ.

Sheet 03_CURVA_MODELOS
A1: Curva de especificaciones M1–M4 | B1: Curva de especificaciones M1–M4 | C1: Curva de especificaciones M1–M4 | D1: Curva de especificaciones M1–M4 | E1: Curva de especificaciones M1–M4 | F1: Curva de especificaciones M1–M4 | G1: Curva de especificaciones M1–M4 | H1: Curva de especificaciones M1–M4 | I1: Curva de especificaciones M1–M4 | J1: Curva de especificaciones M1–M4 | K1: Curva de especificaciones M1–M4 | L1: Curva de especificaciones M1–M4 | M1: Curva de especificaciones M1–M4
A2: Se muestran todas las especificaciones defendibles. No se elige retrospectivamente el modelo que produzca el porcentaje más conveniente. | B2: Se muestran todas las especificaciones defendibles. No se elige retrospectivamente el modelo que produzca el porcentaje más conveniente. | C2: Se muestran todas las especificaciones defendibles. No se elige retrospectivamente el modelo que produzca el porcentaje más conveniente. | D2: Se muestran todas las especificaciones defendibles. No se elige retrospectivamente el modelo que produzca el porcentaje más conveniente. | E2: Se muestran todas las especificaciones defendibles. No se elige retrospectivamente el modelo que produzca el porcentaje más conveniente. | F2: Se muestran todas las especificaciones defendibles. No se elige retrospectivamente el modelo que produzca el porcentaje más conveniente. | G2: Se muestran todas las especificaciones defendibles. No se elige retrospectivamente el modelo que produzca el porcentaje más conveniente. | H2: Se muestran todas las especificaciones defendibles. No se elige retrospectivamente el modelo que produzca el porcentaje más conveniente. | I2: Se muestran todas las especificaciones defendibles. No se elige retrospectivamente el modelo que produzca el porcentaje más conveniente. | J2: Se muestran todas las especificaciones defendibles. No se elige retrospectivamente el modelo que produzca el porcentaje más conveniente. | K2: Se muestran todas las especificaciones defendibles. No se elige retrospectivamente el modelo que produzca el porcentaje más conveniente. | L2: Se muestran todas las especificaciones defendibles. No se elige retrospectivamente el modelo que produzca el porcentaje más conveniente. | M2: Se muestran todas las especificaciones defendibles. No se elige retrospectivamente el modelo que produzca el porcentaje más conveniente.
A5: Modelo | B5: Registrados media | C5: Registrados mediana | D5: Reg. P2,5 | E5: Reg. P97,5 | F5: Probables media | G5: Probables mediana | H5: VP P2,5 | I5: VP P97,5 | J5: Δ primario reg. (pp) | K5: Parámetros | L5: Inferencia | M5: Estado
A6: M1 | B6: =AVERAGE('09_BASE_AUDITABLE'!$Y$2:$Y$4001) -> 0.48602533 | C6: =MEDIAN('09_BASE_AUDITABLE'!$Y$2:$Y$4001) -> 0.48608095 | D6: =PERCENTILE('09_BASE_AUDITABLE'!$Y$2:$Y$4001,0.025) -> 0.47001267 | E6: =PERCENTILE('09_BASE_AUDITABLE'!$Y$2:$Y$4001,0.975) -> 0.50274572 | F6: =AVERAGE('09_BASE_AUDITABLE'!$AC$2:$AC$4001) -> 0.47916707 | G6: =MEDIAN('09_BASE_AUDITABLE'!$AC$2:$AC$4001) -> 0.47915794 | H6: =PERCENTILE('09_BASE_AUDITABLE'!$AC$2:$AC$4001,0.025) -> 0.46381858 | I6: =PERCENTILE('09_BASE_AUDITABLE'!$AC$2:$AC$4001,0.975) -> 0.49496819 | J6: =(C6-$C$8)*100 -> 0.0019240894 | K6: 21 | L6: MAP + aproximación condicional Laplace/Fisher | M6: CUMPLE
A7: M2 | B7: =AVERAGE('09_BASE_AUDITABLE'!$Z$2:$Z$4001) -> 0.48606362 | C7: =MEDIAN('09_BASE_AUDITABLE'!$Z$2:$Z$4001) -> 0.48597168 | D7: =PERCENTILE('09_BASE_AUDITABLE'!$Z$2:$Z$4001,0.025) -> 0.46966587 | E7: =PERCENTILE('09_BASE_AUDITABLE'!$Z$2:$Z$4001,0.975) -> 0.5028928 | F7: =AVERAGE('09_BASE_AUDITABLE'!$AD$2:$AD$4001) -> 0.47912558 | G7: =MEDIAN('09_BASE_AUDITABLE'!$AD$2:$AD$4001) -> 0.47893049 | H7: =PERCENTILE('09_BASE_AUDITABLE'!$AD$2:$AD$4001,0.025) -> 0.46325238 | I7: =PERCENTILE('09_BASE_AUDITABLE'!$AD$2:$AD$4001,0.975) -> 0.49525174 | J7: =(C7-$C$8)*100 -> -0.0090025633 | K7: 24 | L7: MAP + aproximación condicional Laplace/Fisher | M7: CUMPLE
A8: M3 (primario) | B8: =AVERAGE('09_BASE_AUDITABLE'!$AA$2:$AA$4001) -> 0.48586581 | C8: =MEDIAN('09_BASE_AUDITABLE'!$AA$2:$AA$4001) -> 0.4860617 | D8: =PERCENTILE('09_BASE_AUDITABLE'!$AA$2:$AA$4001,0.025) -> 0.46890807 | E8: =PERCENTILE('09_BASE_AUDITABLE'!$AA$2:$AA$4001,0.975) -> 0.50249399 | F8: =AVERAGE('09_BASE_AUDITABLE'!$AE$2:$AE$4001) -> 0.47895192 | G8: =MEDIAN('09_BASE_AUDITABLE'!$AE$2:$AE$4001) -> 0.47889686 | H8: =PERCENTILE('09_BASE_AUDITABLE'!$AE$2:$AE$4001,0.025) -> 0.46222293 | I8: =PERCENTILE('09_BASE_AUDITABLE'!$AE$2:$AE$4001,0.975) -> 0.49540912 | J8: =(C8-$C$8)*100 -> 0 | K8: 267 | L8: NUTS (nutpie) | M8: CUMPLE
A9: M4 (robustez P99) | B9: =AVERAGE('09_BASE_AUDITABLE'!$AB$2:$AB$4001) -> 0.48852355 | C9: =MEDIAN('09_BASE_AUDITABLE'!$AB$2:$AB$4001) -> 0.48859345 | D9: =PERCENTILE('09_BASE_AUDITABLE'!$AB$2:$AB$4001,0.025) -> 0.47307452 | E9: =PERCENTILE('09_BASE_AUDITABLE'!$AB$2:$AB$4001,0.975) -> 0.50350621 | F9: =AVERAGE('09_BASE_AUDITABLE'!$AF$2:$AF$4001) -> 0.48423937 | G9: =MEDIAN('09_BASE_AUDITABLE'!$AF$2:$AF$4001) -> 0.48437413 | H9: =PERCENTILE('09_BASE_AUDITABLE'!$AF$2:$AF$4001,0.025) -> 0.4682383 | I9: =PERCENTILE('09_BASE_AUDITABLE'!$AF$2:$AF$4001,0.975) -> 0.49983827 | J9: =(C9-$C$8)*100 -> 0.25317489 | K9: 267 | L9: MAP + aproximación Laplace/Fisher con pseudo-verosimilitud calibrada P99 | M9: CUMPLE
A12: Resumen de dependencia de especificación | B12: Resumen de dependencia de especificación | C12: Resumen de dependencia de especificación | D12: Resumen de dependencia de especificación | E12: Resumen de dependencia de especificación | F12: Resumen de dependencia de especificación
A13: Métrica | B13: Valor | C13: Umbral orientativo | D13: Estado
A14: Mínimo mediano registrados | B14: =MIN(C6:C9) -> 0.48597168
A15: Máximo mediano registrados | B15: =MAX(C6:C9) -> 0.48859345
A16: Rango M1–M4 | B16: =(B15-B14)*100 -> 0.26217745 | C16: ≤ 1,00 pp | D16: =IF(B16<=1,"CUMPLE","REVISAR") -> CUMPLE
A17: Cambio M3→M4 | B17: =(C9-C8)*100 -> 0.25317489 | C17: robustez visible | D17: INFORMATIVO
